Workbook

Sheet Cover
B2: BLDR
B3: Builders FirstSource, Inc. | NYSE: BLDR | Industrials — Building Products
B6: Recommendation | C6: Pitch Date | D6: Target Price | E6: Downside | F6: Current
B7: SELL | C7: December 2025 | D7: =DCF!C46 -> 82.465716 | E7: =DCF!C48 -> -0.23130391 | F7: =Assumptions!C34 -> 107.28
B9: Investment Thesis | SELL
B10: • Weakening end market: single-family starts –12.1% YoY, multi-family –20.1% YoY. BLDR's core revenue tied directly to housing starts — deterioration is not priced in.
B11: • Organic revenue declined 10.6% YoY in Q3 2025. $2.4B in acquisitions masked operational weakness. Growth has been inorganic, not fundamental.
B12: • Margin compression accelerating: EBITDA –30.8% YoY, EBIT –46.5% YoY. ROIC declining sharply, signaling capital efficiency erosion as housing fundamentals weaken.
B13: • Stock trades at 9.6x EV/EBITDA vs. industry median 11.5x — discount reflects market concern but DCF suggests further downside given volume headwinds.
B14: • Pitch validated: BLDR declined ~30% following the December 2025 sell recommendation as housing market headwinds materialized.
B16: Key Assumptions (live from Assumptions tab)
B17: WACC | C17: =Assumptions!C14 -> 0.08511379
B18: Terminal Growth Rate | C18: =Assumptions!C17 -> 0.02
B19: Beta | C19: =Assumptions!C7 -> 1.09
B20: Tax Rate | C20: =Assumptions!C25 -> 0.22
B21: Shares Outstanding (M) | C21: =Assumptions!C33 -> 110.6
B22: Debt ($M) | C22: =Assumptions!C32 -> 4255

Sheet Assumptions
B2: BLDR — Model Assumptions
B4: WACC ASSUMPTIONS
B5: Risk-Free Rate (10-yr Treasury) | C5: 0.0409 | D5: Source: US Treasury, Dec 2025
B6: Equity Risk Premium | C6: 0.055 | D6: Source: Damodaran, Dec 2025
B7: Levered Beta | C7: 1.09 | D7: Source: FactSet, Dec 2025
B8: Cost of Equity | C8: =C5+C7*C6 -> 0.10085
B9: Weight of Equity | C9: 0.713
B10: Pre-Tax Cost of Debt | C10: 0.059
B11: Effective Tax Rate | C11: 0.22
B12: After-Tax Cost of Debt | C12: =C10*(1-C11) -> 0.04602
B13: Weight of Debt | C13: 0.287
B14: WACC | C14: =C8*C9+C12*C13 -> 0.08511379
B16: TERMINAL VALUE ASSUMPTIONS
B17: Terminal Growth Rate (base) | C17: 0.02
B18: EV/EBITDA Exit Multiple (industry avg) | C18: 11.5
B19: EV/EBITDA Exit Multiple (low end) | C19: 8.1
B21: PROJECTION ASSUMPTIONS (Base Case)
B22: Assumption | C22: FY2026 | D22: FY2027 | E22: FY2028 | F22: FY2029 | G22: FY2030
B23: Revenue Growth % | C23: -0.027 | D23: 0.059 | E23: -0.016 | F23: 0.005 | G23: 0.016
B24: EBIT Margin % | C24: 0.042 | D24: 0.064 | E24: 0.053 | F24: 0.053 | G24: 0.057
B25: Tax Rate % | C25: 0.22 | D25: 0.22 | E25: 0.22 | F25: 0.22 | G25: 0.22
B26: D&A / Revenue % | C26: 0.039 | D26: 0.036 | E26: 0.036 | F26: 0.036 | G26: 0.036
B27: Capex ($M, fixed) | C27: -360 | D27: -382 | E27: -382 | F27: -382 | G27: -382
B28: NWC Change ($M) | C28: 35 | D28: -73 | E28: 21 | F28: -7 | G28: -21
B30: BALANCE SHEET INPUTS
B31: Cash & ST Investments ($M) | C31: 296
B32: Total Long-Term Debt ($M) | C32: 4255
B33: Shares Outstanding (M) | C33: 110.6
B34: Current Share Price ($) | C34: 107.28

Sheet Financials
B2: Builders FirstSource, Inc. (BLDR) — Historical Financials ($M)
B5: Line Item ($M) | C5: FY2021 | D5: FY2022 | E5: FY2023 | F5: FY2024 | G5: FY2025E
B6: INCOME STATEMENT
B7: Revenue | C7: 11839 | D7: 22726 | E7: 17097 | F7: 16400 | G7: 15100
B8: YoY Growth % | E8: =IFERROR((E7-D7)/D7,"") -> -0.24768987 | F8: =IFERROR((F7-E7)/E7,"") -> -0.040767386 | G8: =IFERROR((G7-F7)/F7,"") -> -0.079268293 | H8: =IFERROR((H7-G7)/G7,"") -> -1
B9: Gross Profit | C9: 2812 | D9: 5879 | E9: 5101 | F9: 4933 | G9: 4544
B10: Gross Margin % | C10: =IFERROR(C9/C7,"") -> 0.23752006 | D10: =IFERROR(D9/D7,"") -> 0.25869049 | E10: =IFERROR(E9/E7,"") -> 0.29835644 | F10: =IFERROR(F9/F7,"") -> 0.30079268 | G10: =IFERROR(G9/G7,"") -> 0.30092715
B11: EBITDA | C11: 2261 | D11: 4458 | E11: 2744 | F11: 2201 | G11: 1625
B12: D&A | C12: 551 | D12: 529 | E12: 558 | F12: 562 | G12: 440
B13: EBIT | C13: 1710 | D13: 3929 | E13: 2176 | F13: 1595 | G13: 724
B14: EBIT Margin % | C14: =IFERROR(C13/C7,"") -> 0.14443787 | D14: =IFERROR(D13/D7,"") -> 0.17288568 | E14: =IFERROR(E13/E7,"") -> 0.12727379 | F14: =IFERROR(F13/F7,"") -> 0.097256098 | G14: =IFERROR(G13/G7,"") -> 0.04794702
B15: Net Income | C15: 769 | D15: 2738 | E15: 1689 | F15: 1239 | G15: 555
B16: BALANCE SHEET
B17: Cash & ST Investments | C17: 1040 | D17: 617 | E17: 439 | F17: 296
B18: Total Debt | C18: 2783 | D18: 2986 | E18: 2986 | F18: 3513 | G18: 4255
B19: KEY METRICS
B20: Capex | C20: 289 | D20: 366 | E20: 430 | F20: 367 | G20: 259
B21: ROIC % | E21: 0.072 | F21: 0.062 | G21: 0.036
B22: Net Debt | C22: =IFERROR(C20-C19,"") -> 289 | D22: =IFERROR(D20-D19,"") -> 366 | E22: =IFERROR(E20-E19,"") -> 430 | F22: =IFERROR(F20-F19,"") -> 367 | G22: =IFERROR(G20-G19,"") -> 259

Sheet DCF
B2: Builders FirstSource (BLDR) — DCF Model | SELL | Dec 2025
B3: \
C5: ◄ Historical | F5: Projected ►
B6: FCF Build ($M) | C6: FY2023 | D6: FY2024 | E6: FY2025E | F6: FY2026E | G6: FY2027E | H6: FY2028E | I6: FY2029E | J6: FY2030E
B7: Revenue ($M) | C7: =Financials!E7 -> 17097 | D7: =Financials!F7 -> 16400 | E7: =Financials!G7 -> 15100 | F7: =E7*(1+Assumptions!C23) -> 14692.3 | G7: =F7*(1+Assumptions!D23) -> 15559.146 | H7: =G7*(1+Assumptions!E23) -> 15310.199 | I7: =H7*(1+Assumptions!F23) -> 15386.75 | J7: =I7*(1+Assumptions!G23) -> 15632.938
B8: Revenue Growth (YoY%) | D8: =IFERROR((D7-C7)/C7,"") -> -0.040767386 | E8: =IFERROR((E7-D7)/D7,"") -> -0.079268293 | F8: =IFERROR((F7-E7)/E7,"") -> -0.027 | G8: =IFERROR((G7-F7)/F7,"") -> 0.059 | H8: =IFERROR((H7-G7)/G7,"") -> -0.016 | I8: =IFERROR((I7-H7)/H7,"") -> 0.005 | J8: =IFERROR((J7-I7)/I7,"") -> 0.016
B9: EBIT ($M) | C9: =Financials!E13 -> 2176 | D9: =Financials!F13 -> 1595 | E9: =Financials!G13 -> 724 | F9: =F7*Assumptions!C24 -> 617.0766 | G9: =G7*Assumptions!D24 -> 995.78532 | H9: =H7*Assumptions!E24 -> 811.44057 | I9: =I7*Assumptions!F24 -> 815.49777 | J9: =J7*Assumptions!G24 -> 891.07749
B10: EBIT Margin % | C10: =IFERROR(C9/C7,"") -> 0.12727379 | D10: =IFERROR(D9/D7,"") -> 0.097256098 | E10: =IFERROR(E9/E7,"") -> 0.04794702 | F10: =IFERROR(F9/F7,"") -> 0.042 | G10: =IFERROR(G9/G7,"") -> 0.064 | H10: =IFERROR(H9/H7,"") -> 0.053 | I10: =IFERROR(I9/I7,"") -> 0.053 | J10: =IFERROR(J9/J7,"") -> 0.057
B11: NOPAT | C11: =C9*(1-0.233) -> 1668.992 | D11: =D9*(1-0.223) -> 1239.315 | E11: =E9*(1-0.233) -> 555.308 | F11: =F9*(1-Assumptions!C25) -> 481.31975 | G11: =G9*(1-Assumptions!D25) -> 776.71255 | H11: =H9*(1-Assumptions!E25) -> 632.92364 | I11: =I9*(1-Assumptions!F25) -> 636.08826 | J11: =J9*(1-Assumptions!G25) -> 695.04044
B12: (+) D&A ($M) | C12: =Financials!E12 -> 558 | D12: =Financials!F12 -> 562 | E12: =Financials!G12 -> 440 | F12: =F7*Assumptions!C26 -> 572.9997 | G12: =G7*Assumptions!D26 -> 560.12925 | H12: =H7*Assumptions!E26 -> 551.16718 | I12: =I7*Assumptions!F26 -> 553.92301 | J12: =J7*Assumptions!G26 -> 562.78578
B13: (−) Change in NWC ($M) | F13: =Assumptions!C28 -> 35 | G13: =Assumptions!D28 -> -73 | H13: =Assumptions!E28 -> 21 | I13: =Assumptions!F28 -> -7 | J13: =Assumptions!G28 -> -21
B14: (−) Capex ($M) | F14: =Assumptions!C27 -> -360 | G14: =Assumptions!D27 -> -382 | H14: =Assumptions!E27 -> -382 | I14: =Assumptions!F27 -> -382 | J14: =Assumptions!G27 -> -382
B16: Unlevered Free Cash Flow
B17: Unlevered FCF ($M) | F17: =F11+F12+F13+F14 -> 729.31945 | G17: =G11+G12+G13+G14 -> 881.8418 | H17: =H11+H12+H13+H14 -> 823.09082 | I17: =I11+I12+I13+I14 -> 801.01127 | J17: =J11+J12+J13+J14 -> 854.82622
B19: Discount Factors
B20: WACC | F20: =Assumptions!C14 -> 0.08511379 | G20: =Assumptions!C14 -> 0.08511379 | H20: =Assumptions!C14 -> 0.08511379 | I20: =Assumptions!C14 -> 0.08511379 | J20: =Assumptions!C14 -> 0.08511379
B21: Period | F21: 1 | G21: 2 | H21: 3 | I21: 4 | J21: 5
B22: Discount Factor [1/(1+WACC)^n] | F22: =1/(1+$F$20)^F21 -> 0.92156234 | G22: =1/(1+$F$20)^G21 -> 0.84927714 | H22: =1/(1+$F$20)^H21 -> 0.78266183 | I22: =1/(1+$F$20)^I21 -> 0.72127166 | J22: =1/(1+$F$20)^J21 -> 0.6646968
B23: Discounted FCF ($M) | F23: =F17*F22 -> 672.11333 | G23: =G17*G22 -> 748.92808 | H23: =H17*H22 -> 644.20176 | I23: =I17*I22 -> 577.74673 | J23: =J17*J22 -> 568.20025
B24: Sum of Discounted FCFs ($M) | F24: =SUM(F23:J23) -> 3211.1902
B26: Terminal Value Calculations
B27: Method 1: Growing Perpetuity
B28: Terminal Growth Rate | C28: =Assumptions!C17 -> 0.02
B29: Year 5 FCF ($M) | C29: =J17 -> 854.82622
B30: Terminal Value [FCF5×(1+g)/(WACC−g)] | C30: =C29*(1+C28)/($F$20-C28) -> 13390.754
B31: Discounted Terminal Value | C31: =C30/(1+$F$20)^5 -> 8900.7913
B32: Total Enterprise Value | C32: =F24+C31 -> 12111.981
B33: Implied Share Price (Method 1) | C33: =(C32-Assumptions!C32+Assumptions!C31)/Assumptions!C33 -> 73.715927
B35: Method 2: EV/EBITDA Exit Multiple (Industry Avg)
B36: Projected FY2030 EBITDA ($M) | C36: =J17+J12 -> 1417.612
B37: EV/EBITDA Multiple (industry avg) | C37: =Assumptions!C18 -> 11.5
B38: 2030 Terminal EV | C38: =C36*C37 -> 16302.538
B39: Discounted Terminal EV | C39: =C38/(1+$F$20)^5 -> 10836.245
B40: Total Enterprise Value | C40: =F24+C39 -> 14047.435
B41: Implied Share Price (Method 2 — Avg) | C41: =(C40-Assumptions!C32+Assumptions!C31)/Assumptions!C33 -> 91.215506
B43: Weighted Average Target Price
B44: Method 1 Weight | C44: 0.5
B45: Method 2 Weight | C45: 0.5
B46: Weighted Average Target Price | C46: =C33*C44+C41*C45 -> 82.465716
B47: Current Share Price | C47: =Assumptions!C34 -> 107.28
...

Sheet Scenarios
B2: Builders FirstSource — Scenario Analysis
B5: Assumption | C5: Bear Case | D5: Base Case | E5: Bull Case
B6: Revenue Growth (FY2030) | C6: -0.05 | D6: =Assumptions!G23 -> 0.016 | E6: 0.06
B7: EBIT Margin % (FY2030) | C7: 0.035 | D7: =Assumptions!G24 -> 0.057 | E7: 0.075
B8: Tax Rate % | C8: 0.24 | D8: =Assumptions!G25 -> 0.22 | E8: 0.2
B9: Terminal Growth Rate | C9: 0 | D9: =Assumptions!C17 -> 0.02 | E9: 0.04
B10: WACC | C10: 0.095 | D10: =Assumptions!C14 -> 0.08511379 | E10: 0.07
B12: Scenario Outputs
B13: Implied Share Price | C13: 47.97 | D13: =DCF!C46 -> 82.465716 | E13: 154.04
B14: vs. Current Price | C14: =(C13-Assumptions!C34)/Assumptions!C34 -> -0.55285235 | D14: =(D13-Assumptions!C34)/Assumptions!C34 -> -0.23130391 | E14: =(E13-Assumptions!C34)/Assumptions!C34 -> 0.43586875

Sheet Comps
B2: Builders FirstSource (BLDR) — Comparable Company Analysis
B3: Source: FactSet, December 2025. All USD millions.
B5: Company | C5: Ticker | D5: Mkt Cap | E5: EV | F5: Revenue | G5: Rev Growth | H5: EBITDA | I5: EBITDA Margin | J5: EV/EBITDA | K5: EV/Sales | L5: P/E (NTM)
B6: Builders FirstSource | C6: BLDR | D6: 11866 | E6: 15273 | F6: 15100 | G6: -0.079 | H6: 1625 | I6: =IFERROR(E6/H6,"-") -> 9.3987692 | J6: =IFERROR(H6/F6,"-") -> 0.10761589 | K6: =IFERROR(E6/F6,"-") -> 1.011457 | L6: 15.78
B7: UFP Industries | C7: UFPI | D7: 5236 | E7: 6100 | F7: 6500 | G7: -0.054 | H7: 578 | I7: =IFERROR(E7/H7,"-") -> 10.553633 | J7: =IFERROR(H7/F7,"-") -> 0.088923077 | K7: =IFERROR(E7/F7,"-") -> 0.93846154 | L7: 16.6
B8: Boise Cascade | C8: BCC | D8: 3800 | E8: 4100 | F8: 6800 | G8: -0.042 | H8: 490 | I8: =IFERROR(E8/H8,"-") -> 8.3673469 | J8: =IFERROR(H8/F8,"-") -> 0.072058824 | K8: =IFERROR(E8/F8,"-") -> 0.60294118 | L8: 13.2
B9: Louisiana-Pacific | C9: LPX | D9: 5200 | E9: 5600 | F9: 2900 | G9: 0.031 | H9: 520 | I9: =IFERROR(E9/H9,"-") -> 10.769231 | J9: =IFERROR(H9/F9,"-") -> 0.17931034 | K9: =IFERROR(E9/F9,"-") -> 1.9310345 | L9: 19.4
B10: Trex Company | C10: TREX | D10: 6800 | E10: 7000 | F10: 1100 | G10: 0.072 | H10: 290 | I10: =IFERROR(E10/H10,"-") -> 24.137931 | J10: =IFERROR(H10/F10,"-") -> 0.26363636 | K10: =IFERROR(E10/F10,"-") -> 6.3636364 | L10: 36.2
B11: Mean | C11: — | D11: =IFERROR(AVERAGE(IF(ISNUMBER(D6:D10),D6:D10)),"") | E11: =IFERROR(AVERAGE(IF(ISNUMBER(E6:E10),E6:E10)),"") | F11: =IFERROR(AVERAGE(IF(ISNUMBER(F6:F10),F6:F10)),"") | H11: =IFERROR(AVERAGE(IF(ISNUMBER(H6:H10),H6:H10)),"") | I11: =IFERROR(AVERAGE(IF(ISNUMBER(I6:I10),I6:I10)),"") | J11: =IFERROR(AVERAGE(IF(ISNUMBER(J6:J10),J6:J10)),"") | K11: =IFERROR(AVERAGE(IF(ISNUMBER(K6:K10),K6:K10)),"") | L11: =IFERROR(AVERAGE(IF(ISNUMBER(L6:L10),L6:L10)),"")
B12: Median | C12: — | D12: =IFERROR(MEDIAN(IF(ISNUMBER(D6:D10),D6:D10)),"") | E12: =IFERROR(MEDIAN(IF(ISNUMBER(E6:E10),E6:E10)),"") | F12: =IFERROR(MEDIAN(IF(ISNUMBER(F6:F10),F6:F10)),"") | H12: =IFERROR(MEDIAN(IF(ISNUMBER(H6:H10),H6:H10)),"") | I12: =IFERROR(MEDIAN(IF(ISNUMBER(I6:I10),I6:I10)),"") | J12: =IFERROR(MEDIAN(IF(ISNUMBER(J6:J10),J6:J10)),"") | K12: =IFERROR(MEDIAN(IF(ISNUMBER(K6:K10),K6:K10)),"") | L12: =IFERROR(MEDIAN(IF(ISNUMBER(L6:L10),L6:L10)),"")

Sheet Football Field
B2: Builders FirstSource (BLDR) — Valuation Football Field | SELL
B5: Methodology | C5: Low | D5: Base | E5: High | F5: Current Price
B6: DCF — Growing Perpetuity | C6: =DCF!C33*0.58 -> 42.755237 | D6: =DCF!C33 -> 73.715927 | E6: =DCF!C33*1.51 -> 111.31105 | F6: =Assumptions!C34 -> 107.28
B7: DCF — EV/EBITDA Exit (Avg) | C7: =DCF!C41*0.58 -> 52.904994 | D7: =DCF!C41 -> 91.215506 | E7: =DCF!C41*1.48 -> 134.99895 | F7: =Assumptions!C34 -> 107.28
B8: 52-Week Trading Range | C8: =94.35 -> 94.35 | D8: =122.69 -> 122.69 | E8: =151.03 -> 151.03 | F8: =Assumptions!C34 -> 107.28
B9: Analyst Consensus (FactSet) | C9: =115 -> 115 | D9: =134.88 -> 134.88 | E9: =154 -> 154 | F9: =Assumptions!C34 -> 107.28
B11: WEIGHTED AVERAGE TARGET PRICE | D11: =DCF!C46 -> 82.465716 | E11: =DCF!C48 -> -0.23130391 | F11: =Assumptions!C34 -> 107.28
