Workbook

Sheet Cover
B2: MTN
B3: Vail Resorts, Inc. | NYSE: MTN | Consumer Discretionary — Travel, Leisure & Experiences
B6: Recommendation | C6: Pitch Date | D6: Target Price | E6: Downside | F6: Current
B7: SELL | C7: February 2026 | D7: =DCF!C46 -> 88.513516 | E7: =DCF!C48 -> -0.35532763 | F7: =Assumptions!C37 -> 137.3
B9: Investment Thesis | SELL
B10: • Growth ceiling reached: Epic Pass penetration ~75% of visits caps future volume growth. Pass unit sales –2% YoY after 55% expansion over prior 5 years. Growth is now price-led, not volume-led.
B11: • Structural climate risk underpriced: snowpack projected to decline 20–30% by 2050. Early-season snowfall already –60% YoY in FY2026. Skier visits down 8% in 2023-24 on 28% annual snowfall drop.
B12: • High fixed-cost operating leverage amplifies earnings risk: SG&A sticky at 13–15% of revenue. Small visitation changes drive EPS swings of –67% to +173% YoY.
B13: • Valuation premium not justified: MTN at 21.3x forward P/E vs. Consumer Discretionary average 15.8x and peer median 10.7x — despite EBITDA settling into low-single-digit growth.
B14: • Pitch validated: MTN declined significantly post-pitch as Q3 2026 earnings were hit by historic weather challenges, with guidance cut and visitation well below expectations.
B16: Key Assumptions (live from Assumptions tab)
B17: WACC (Override) | C17: =Assumptions!C15 -> 0.09
B18: Terminal Growth Rate | C18: =Assumptions!C18 -> 0.015
B19: EV/EBITDA Exit Multiple | C19: =Assumptions!C19 -> 8
B20: Tax Rate | C20: =Assumptions!C27 -> 0.25
B21: Shares Outstanding (M) | C21: =Assumptions!C36 -> 35.91
B22: Net Debt ($M) | C22: =Assumptions!C34-Assumptions!C33 -> 2819

Sheet Assumptions
B2: MTN — Model Assumptions
B4: WACC ASSUMPTIONS
B5: Risk-Free Rate (10-yr Treasury) | C5: 0.042 | D5: Source: US Treasury, Feb 2026
B6: Equity Risk Premium | C6: 0.055 | D6: Source: Damodaran, Feb 2026
B7: Levered Beta | C7: 0.9 | D7: Source: FactSet, Feb 2026
B8: Cost of Equity | C8: =C5+C7*C6 -> 0.0915
B9: Weight of Equity | C9: 0.59
B10: Pre-Tax Cost of Debt | C10: 0.053
B11: Effective Tax Rate | C11: 0.25
B12: After-Tax Cost of Debt | C12: =C10*(1-C11) -> 0.03975
B13: Weight of Debt | C13: 0.41
B14: WACC | C14: =C8*C9+C12*C13 -> 0.0702825
B15: Model WACC Used (override) | C15: 0.09
B17: TERMINAL VALUE ASSUMPTIONS
B18: Terminal Growth Rate (base) | C18: 0.015
B19: EV/EBITDA Exit Multiple (base) | C19: 8
B20: EV/EBITDA Exit Multiple (bear) | C20: 6
B22: PROJECTION ASSUMPTIONS (Base Case)
B23: Assumption | C23: FY2025 | D23: FY2026 | E23: FY2027 | F23: FY2028 | G23: FY2029
B24: Revenue Growth % | C24: 0.023 | D24: 0.03 | E24: 0.025 | F24: 0.025 | G24: 0.02
B25: EBITDA Margin % | C25: 0.27 | D25: 0.27 | E25: 0.27 | F25: 0.27 | G25: 0.27
B26: EBIT Margin % | C26: 0.17 | D26: 0.173 | E26: 0.173 | F26: 0.167 | G26: 0.169
B27: Tax Rate % | C27: 0.25 | D27: 0.25 | E27: 0.25 | F27: 0.25 | G27: 0.25
B28: D&A ($M fixed) | C28: 296 | D28: 297 | E28: 305 | F28: 330 | G28: 330
B29: Capex ($M fixed) | C29: -208 | D29: -208 | E29: -219 | F29: -257 | G29: -262
B30: NWC Change ($M) | C30: -1 | D30: -1 | E30: -1 | F30: -1 | G30: -1
B32: BALANCE SHEET INPUTS
B33: Cash & ST Investments ($M) | C33: 601
B34: Total Long-Term Debt ($M) | C34: 3420
B35: Noncontrolling Interest ($M) | C35: 312
B36: Shares Outstanding (M) | C36: 35.91
B37: Current Share Price ($) | C37: 137.3

Sheet Financials
B2: Vail Resorts, Inc. (MTN) — Historical Financials ($M)
B3: Source: FactSet / SEC 10-K filings. All USD millions.
B5: Line Item ($M) | C5: FY2020 | D5: FY2021 | E5: FY2022 | F5: FY2023 | G5: FY2024 | H5: FY2025E
B6: INCOME STATEMENT
B7: Revenue | C7: 1278 | D7: 1541 | E7: 2085 | F7: 2891 | G7: 2896 | H7: 2964
B8: YoY Growth % | E8: =IFERROR((E7-D7)/D7,"") -> 0.35301752 | F8: =IFERROR((F7-E7)/E7,"") -> 0.38657074 | G8: =IFERROR((G7-F7)/F7,"") -> 0.0017295054 | H8: =IFERROR((H7-G7)/G7,"") -> 0.023480663 | I8: =IFERROR((I7-H7)/H7,"") -> -1
B9: EBITDA | C9: 170 | D9: 415 | E9: 562 | F9: 820 | G9: 838 | H9: 800
B10: D&A | C10: 183 | D10: 195 | E10: 296 | F10: 297 | G10: 296
B11: EBIT | C11: -14 | D11: 220 | E11: 266 | F11: 523 | G11: 542 | H11: 504
B12: EBIT Margin % | C12: =IFERROR(C11/C7,"") -> -0.010954617 | D12: =IFERROR(D11/D7,"") -> 0.14276444 | E12: =IFERROR(E11/E7,"") -> 0.12757794 | F12: =IFERROR(F11/F7,"") -> 0.18090626 | G12: =IFERROR(G11/G7,"") -> 0.1871547 | H12: =IFERROR(H11/H7,"") -> 0.17004049
B13: EBITDA Margin % | C13: =IFERROR(C9/C7,"") -> 0.13302034 | D13: =IFERROR(D9/D7,"") -> 0.26930565 | E13: =IFERROR(E9/E7,"") -> 0.26954436 | F13: =IFERROR(F9/F7,"") -> 0.28363888 | G13: =IFERROR(G9/G7,"") -> 0.28936464 | H13: =IFERROR(H9/H7,"") -> 0.26990553
B14: Net Income | C14: -212 | D14: 35 | E14: 180 | F14: 246 | G14: 280 | H14: 201
B15: EPS (Diluted) | C15: -5.47 | D15: 0.97 | E15: 4.83 | F15: 6.66 | G15: 7.81 | H15: 5.62
B16: BALANCE SHEET
B17: Cash & ST Investments | C17: 405 | D17: 440 | E17: 620 | F17: 628 | G17: 601
B18: Total Debt | C18: 2822 | D18: 2877 | E18: 2877 | F18: 3213 | G18: 3420 | H18: 3420
B19: KEY METRICS
B20: Capex | C20: 127 | D20: 127 | E20: 200 | F20: 210 | G20: 210 | H20: 208
B21: Dividend Per Share | C21: 0 | D21: 4.84 | E21: 7.84 | F21: 8 | G21: 8 | H21: 8.71
B22: EPS YoY Change % | F22: 0.379 | G22: -0.097

Sheet DCF
B2: Vail Resorts, Inc. (MTN) — DCF Model | SELL | Feb 2026
B3: All USD millions except per-share
C5: Historical | E5: Projected
B6: FCF Build ($M) | C6: FY2023 | D6: FY2024 | E6: FY2025E | F6: FY2026E | G6: FY2027E | H6: FY2028E | I6: FY2029E
B7: Revenue ($M) | C7: =Financials!F7 -> 2891 | D7: =Financials!G7 -> 2896 | E7: =D7*(1+Assumptions!C24) -> 2962.608 | F7: =E7*(1+Assumptions!D24) -> 3051.4862 | G7: =F7*(1+Assumptions!E24) -> 3127.7734 | H7: =G7*(1+Assumptions!F24) -> 3205.9677 | I7: =H7*(1+Assumptions!G24) -> 3270.0871
B8: Revenue Growth (YoY%) | D8: =IFERROR((D7-C7)/C7,"") -> 0.0017295054 | E8: =IFERROR((E7-D7)/D7,"") -> 0.023 | F8: =IFERROR((F7-E7)/E7,"") -> 0.03 | G8: =IFERROR((G7-F7)/F7,"") -> 0.025 | H8: =IFERROR((H7-G7)/G7,"") -> 0.025 | I8: =IFERROR((I7-H7)/H7,"") -> 0.02
B9: EBIT ($M) | C9: =Financials!F11 -> 523 | D9: =Financials!G11 -> 542 | E9: =E7*Assumptions!C26 -> 503.64336 | F9: =F7*Assumptions!D26 -> 527.90712 | G9: =G7*Assumptions!E26 -> 541.1048 | H9: =H7*Assumptions!F26 -> 535.39661 | I9: =I7*Assumptions!G26 -> 552.64472
B10: EBIT Margin % | C10: =IFERROR(C9/C7,"") -> 0.18090626 | D10: =IFERROR(D9/D7,"") -> 0.1871547 | E10: =IFERROR(E9/E7,"") -> 0.17 | F10: =IFERROR(F9/F7,"") -> 0.173 | G10: =IFERROR(G9/G7,"") -> 0.173 | H10: =IFERROR(H9/H7,"") -> 0.167 | I10: =IFERROR(I9/I7,"") -> 0.169
B11: NOPAT | C11: =C9*(1-0.25) -> 392.25 | D11: =D9*(1-0.25) -> 406.5 | E11: =E9*(1-Assumptions!C27) -> 377.73252 | F11: =F9*(1-Assumptions!D27) -> 395.93034 | G11: =G9*(1-Assumptions!E27) -> 405.8286 | H11: =H9*(1-Assumptions!F27) -> 401.54746 | I11: =I9*(1-Assumptions!G27) -> 414.48354
B12: (+) D&A ($M) | C12: =Financials!F10 -> 297 | D12: =Financials!G10 -> 296 | E12: =Assumptions!C28 -> 296 | F12: =Assumptions!D28 -> 297 | G12: =Assumptions!E28 -> 305 | H12: =Assumptions!F28 -> 330 | I12: =Assumptions!G28 -> 330
B13: (−) Capex ($M) | E13: =Assumptions!C29 -> -208 | F13: =Assumptions!D29 -> -208 | G13: =Assumptions!E29 -> -219 | H13: =Assumptions!F29 -> -257 | I13: =Assumptions!G29 -> -262
B14: (−) Change in NWC ($M) | E14: =Assumptions!C30 -> -1 | F14: =Assumptions!D30 -> -1 | G14: =Assumptions!E30 -> -1 | H14: =Assumptions!F30 -> -1 | I14: =Assumptions!G30 -> -1
B16: Unlevered Free Cash Flow
B17: Unlevered FCF ($M) | E17: =E11+E12+E13+E14 -> 464.73252 | F17: =F11+F12+F13+F14 -> 483.93034 | G17: =G11+G12+G13+G14 -> 490.8286 | H17: =H11+H12+H13+H14 -> 473.54746 | I17: =I11+I12+I13+I14 -> 481.48354
B19: Discount Factors
B20: WACC (Model Override) | E20: =Assumptions!C15 -> 0.09 | F20: =Assumptions!C15 -> 0.09 | G20: =Assumptions!C15 -> 0.09 | H20: =Assumptions!C15 -> 0.09 | I20: =Assumptions!C15 -> 0.09
B21: Period | E21: 1 | F21: 2 | G21: 3 | H21: 4 | I21: 5
B22: Discount Factor | E22: =1/(1+$E$20)^E21 -> 0.91743119 | F22: =1/(1+$E$20)^F21 -> 0.84167999 | G22: =1/(1+$E$20)^G21 -> 0.77218348 | H22: =1/(1+$E$20)^H21 -> 0.70842521 | I22: =1/(1+$E$20)^I21 -> 0.64993139
B23: Discounted FCF ($M) | E23: =E17*E22 -> 426.36011 | F23: =F17*F22 -> 407.31448 | G23: =G17*G22 -> 379.00973 | H23: =H17*H22 -> 335.47296 | I23: =I17*I22 -> 312.93126
B24: Sum of Discounted FCFs ($M) | E24: =SUM(E23:I23) -> 1861.0886
B26: Terminal Value Calculations
B27: Method 1: EV/EBITDA Exit Multiple (Base)
B28: Projected FY2029 EBITDA ($M) | C28: =I7*Assumptions!C25 -> 882.92351
B29: EV/EBITDA Exit Multiple | C29: =Assumptions!C19 -> 8
B30: Terminal Enterprise Value | C30: =C28*C29 -> 7063.3881
B31: Discounted Terminal EV | C31: =C30/(1+$E$20)^5 -> 4590.7176
B32: Total Enterprise Value | C32: =E24+C31 -> 6451.8062
B33: Implied Share Price (EV/EBITDA — Base) | C33: =(C32-Assumptions!C34-Assumptions!C35+Assumptions!C33)/Assumptions!C36 -> 92.475805
B35: Method 2: Growing Perpetuity
B36: Terminal Growth Rate | C36: =Assumptions!C18 -> 0.015
B37: Year 5 FCF ($M) | C37: =I17 -> 481.48354
B38: Terminal Value | C38: =C37*(1+C36)/($E$20-C36) -> 6516.0772
B39: Discounted Terminal Value | C39: =C38/(1+$E$20)^5 -> 4235.0031
B40: Total Enterprise Value | C40: =E24+C39 -> 6096.0916
B41: Implied Share Price (Growing Perpetuity) | C41: =(C40-Assumptions!C34-Assumptions!C35+Assumptions!C33)/Assumptions!C36 -> 82.570082
B43: Weighted Average Target Price
B44: Method 1 Weight (EV/EBITDA) | C44: 0.6
B45: Method 2 Weight (Growing Perpetuity) | C45: 0.4
B46: Weighted Average Target Price | C46: =C33*C44+C41*C45 -> 88.513516
B47: Current Share Price | C47: =Assumptions!C37 -> 137.3
...

Sheet Scenarios
B2: Vail Resorts — Scenario Analysis
B5: Assumption | C5: Bear Case | D5: Base Case | E5: Bull Case
B6: Revenue Growth (FY2029) | C6: 0.005 | D6: =Assumptions!G24 -> 0.02 | E6: 0.06
B7: EBITDA Margin % | C7: 0.24 | D7: =Assumptions!C25 -> 0.27 | E7: 0.3
B8: EV/EBITDA Exit Multiple | C8: 6 | D8: =Assumptions!C19 -> 8 | E8: 9.5
B9: Terminal Growth Rate | C9: 0.005 | D9: =Assumptions!C18 -> 0.015 | E9: 0.025
B10: WACC | C10: 0.1 | D10: =Assumptions!C15 -> 0.09 | E10: 0.07
B12: Scenario Outputs
B13: Implied Share Price | C13: 65.33 | D13: =DCF!C46 -> 88.513516 | E13: 123.55
B14: vs. Current Price | C14: =(C13-Assumptions!C37)/Assumptions!C37 -> -0.52418063 | D14: =(D13-Assumptions!C37)/Assumptions!C37 -> -0.35532763 | E14: =(E13-Assumptions!C37)/Assumptions!C37 -> -0.10014567

Sheet Comps
B2: Vail Resorts (MTN) — Comparable Company Analysis
B3: Source: FactSet, February 2026. All USD millions.
B5: Company | C5: Ticker | D5: Mkt Cap | E5: EV | F5: Revenue | G5: Rev Growth | H5: EBITDA | I5: EBITDA Margin | J5: EV/EBITDA | K5: EV/Sales | L5: P/E (NTM)
B6: Vail Resorts | C6: MTN | D6: 5110 | E6: 8241 | F6: 2896 | G6: 0.002 | H6: 838 | I6: =IFERROR(H6/F6,"-") -> 0.28936464 | J6: =IFERROR(E6/H6,"-") -> 9.8341289 | K6: =IFERROR(E6/F6,"-") -> 2.8456492 | L6: 21.3
B7: Travel + Leisure | C7: TNL | D7: 2800 | E7: 10061 | F7: 4000 | G7: 0.041 | H7: 836 | I7: =IFERROR(H7/F7,"-") -> 0.209 | J7: =IFERROR(E7/H7,"-") -> 12.034689 | K7: =IFERROR(E7/F7,"-") -> 2.51525 | L7: 10.4
B8: Six Flags Entertainment | C8: FUN | D8: 1900 | E8: 7268 | F8: 2900 | G8: 0.311 | H8: 729 | I8: =IFERROR(H8/F8,"-") -> 0.25137931 | J8: =IFERROR(E8/H8,"-") -> 9.9698217 | K8: =IFERROR(E8/F8,"-") -> 2.5062069 | L8: 17
B9: United Parks & Resorts | C9: PRKS | D9: 1400 | E9: 4065 | F9: 1200 | G9: -0.033 | H9: 407 | I9: =IFERROR(H9/F9,"-") -> 0.33916667 | J9: =IFERROR(E9/H9,"-") -> 9.987715 | K9: =IFERROR(E9/F9,"-") -> 3.3875 | L9: 10.9
B10: Hilton Grand Vacations | C10: HGV | D10: 2700 | E10: 11047 | F10: 3700 | G10: 0.06 | H10: 605 | I10: =IFERROR(H10/F10,"-") -> 0.16351351 | J10: =IFERROR(E10/H10,"-") -> 18.259504 | K10: =IFERROR(E10/F10,"-") -> 2.9856757
B11: Marriott Vacations | C11: VAC | D11: 1900 | E11: 7045 | F11: 5000 | G11: 0.042 | H11: 705 | I11: =IFERROR(H11/F11,"-") -> 0.141 | J11: =IFERROR(E11/H11,"-") -> 9.9929078 | K11: =IFERROR(E11/F11,"-") -> 1.409 | L11: 13.2
B12: Mean | C12: — | D12: =IFERROR(AVERAGE(IF(ISNUMBER(D6:D11),D6:D11)),"") | E12: =IFERROR(AVERAGE(IF(ISNUMBER(E6:E11),E6:E11)),"") | F12: =IFERROR(AVERAGE(IF(ISNUMBER(F6:F11),F6:F11)),"") | H12: =IFERROR(AVERAGE(IF(ISNUMBER(H6:H11),H6:H11)),"") | I12: =IFERROR(AVERAGE(IF(ISNUMBER(I6:I11),I6:I11)),"") | J12: =IFERROR(AVERAGE(IF(ISNUMBER(J6:J11),J6:J11)),"") | K12: =IFERROR(AVERAGE(IF(ISNUMBER(K6:K11),K6:K11)),"") | L12: =IFERROR(AVERAGE(IF(ISNUMBER(L6:L11),L6:L11)),"")
B13: Median | C13: — | D13: =IFERROR(MEDIAN(IF(ISNUMBER(D6:D11),D6:D11)),"") | E13: =IFERROR(MEDIAN(IF(ISNUMBER(E6:E11),E6:E11)),"") | F13: =IFERROR(MEDIAN(IF(ISNUMBER(F6:F11),F6:F11)),"") | H13: =IFERROR(MEDIAN(IF(ISNUMBER(H6:H11),H6:H11)),"") | I13: =IFERROR(MEDIAN(IF(ISNUMBER(I6:I11),I6:I11)),"") | J13: =IFERROR(MEDIAN(IF(ISNUMBER(J6:J11),J6:J11)),"") | K13: =IFERROR(MEDIAN(IF(ISNUMBER(K6:K11),K6:K11)),"") | L13: =IFERROR(MEDIAN(IF(ISNUMBER(L6:L11),L6:L11)),"")

Sheet Football Field
B2: Vail Resorts (MTN) — Valuation Football Field | SELL
B5: Methodology | C5: Low | D5: Base | E5: High | F5: Current Price
B6: DCF — EV/EBITDA Exit (6x–9.5x) | C6: =DCF!C33*0.66 -> 61.034032 | D6: =DCF!C33 -> 92.475805 | E6: =DCF!C33*1.25 -> 115.59476 | F6: =Assumptions!C37 -> 137.3
B7: DCF — Growing Perpetuity (0.5%–2.5% TGR) | C7: =DCF!C41*0.65 -> 53.670553 | D7: =DCF!C41 -> 82.570082 | E7: =DCF!C41*1.25 -> 103.2126 | F7: =Assumptions!C37 -> 137.3
B8: EV/EBITDA Comps (7x–10x applied to LTM) | C8: 90.00 | D8: 110.00 | E8: 135.00 | F8: =Assumptions!C37 -> 137.3
B9: 52-Week Trading Range | C9: 126.15 | D9: 150.83 | E9: 175.51 | F9: =Assumptions!C37 -> 137.3
B11: WEIGHTED AVERAGE TARGET PRICE | D11: =DCF!C46 -> 88.513516 | E11: =DCF!C48 -> -0.35532763 | F11: =Assumptions!C37 -> 137.3
